Workbook

Sheet Dashboard
A1: PureTask Implementation Tracking — Dashboard
A2: Document 16 — Status of all CHG items from Doc 15 Lovable Implementation Brief
A4: Status Summary
A5: Status | B5: Count | C5: % of Total
A6: Not Started | B6: =COUNTIF(Items!E:E,"Not Started") -> 90 | C6: =B6/90 -> 1
A7: In Progress | B7: =COUNTIF(Items!E:E,"In Progress") -> 0 | C7: =B7/90 -> 0
A8: Blocked | B8: =COUNTIF(Items!E:E,"Blocked") -> 0 | C8: =B8/90 -> 0
A9: Done | B9: =COUNTIF(Items!E:E,"Done") -> 0 | C9: =B9/90 -> 0
A10: Verified | B10: =COUNTIF(Items!E:E,"Verified") -> 0 | C10: =B10/90 -> 0
A11: Total | B11: =SUM(B6:B10) -> 90 | C11: =B11/90 -> 1
A13: Priority Breakdown
A14: Priority | B14: Total | C14: Done + Verified | D14: % Complete
A15: P0 | B15: =COUNTIF(Items!D:D,"P0") -> 62 | C15: =COUNTIFS(Items!D:D,"P0",Items!E:E,"Done")+COUNTIFS(Items!D:D,"P0",Items!E:E,"Verified") -> 0 | D15: =IFERROR(C15/B15,0) -> 0
A16: P1 | B16: =COUNTIF(Items!D:D,"P1") -> 25 | C16: =COUNTIFS(Items!D:D,"P1",Items!E:E,"Done")+COUNTIFS(Items!D:D,"P1",Items!E:E,"Verified") -> 0 | D16: =IFERROR(C16/B16,0) -> 0
A17: P2 | B17: =COUNTIF(Items!D:D,"P2") -> 3 | C17: =COUNTIFS(Items!D:D,"P2",Items!E:E,"Done")+COUNTIFS(Items!D:D,"P2",Items!E:E,"Verified") -> 0 | D17: =IFERROR(C17/B17,0) -> 0
A18: P3 | B18: =COUNTIF(Items!D:D,"P3") -> 0 | C18: =COUNTIFS(Items!D:D,"P3",Items!E:E,"Done")+COUNTIFS(Items!D:D,"P3",Items!E:E,"Verified") -> 0 | D18: =IFERROR(C18/B18,0) -> 0
A20: Progress by Section
A21: Section | B21: Total Items | C21: Done | D21: Verified | E21: % Complete
A22: 1. Foundation | B22: =COUNTIF(Items!B:B,"1. Foundation") -> 10 | C22: =COUNTIFS(Items!B:B,"1. Foundation",Items!E:E,"Done") -> 0 | D22: =COUNTIFS(Items!B:B,"1. Foundation",Items!E:E,"Verified") -> 0 | E22: =IFERROR((C22+D22)/B22,0) -> 0
A23: 10. SMS Logic | B23: =COUNTIF(Items!B:B,"10. SMS Logic") -> 3 | C23: =COUNTIFS(Items!B:B,"10. SMS Logic",Items!E:E,"Done") -> 0 | D23: =COUNTIFS(Items!B:B,"10. SMS Logic",Items!E:E,"Verified") -> 0 | E23: =IFERROR((C23+D23)/B23,0) -> 0
A24: 11. Trust & Safety | B24: =COUNTIF(Items!B:B,"11. Trust & Safety") -> 7 | C24: =COUNTIFS(Items!B:B,"11. Trust & Safety",Items!E:E,"Done") -> 0 | D24: =COUNTIFS(Items!B:B,"11. Trust & Safety",Items!E:E,"Verified") -> 0 | E24: =IFERROR((C24+D24)/B24,0) -> 0
A25: 12. Reviews | B25: =COUNTIF(Items!B:B,"12. Reviews") -> 1 | C25: =COUNTIFS(Items!B:B,"12. Reviews",Items!E:E,"Done") -> 0 | D25: =COUNTIFS(Items!B:B,"12. Reviews",Items!E:E,"Verified") -> 0 | E25: =IFERROR((C25+D25)/B25,0) -> 0
A26: 13. Accessibility | B26: =COUNTIF(Items!B:B,"13. Accessibility") -> 7 | C26: =COUNTIFS(Items!B:B,"13. Accessibility",Items!E:E,"Done") -> 0 | D26: =COUNTIFS(Items!B:B,"13. Accessibility",Items!E:E,"Verified") -> 0 | E26: =IFERROR((C26+D26)/B26,0) -> 0
A27: 14. Mobile | B27: =COUNTIF(Items!B:B,"14. Mobile") -> 5 | C27: =COUNTIFS(Items!B:B,"14. Mobile",Items!E:E,"Done") -> 0 | D27: =COUNTIFS(Items!B:B,"14. Mobile",Items!E:E,"Verified") -> 0 | E27: =IFERROR((C27+D27)/B27,0) -> 0
A28: 15. Admin | B28: =COUNTIF(Items!B:B,"15. Admin") -> 6 | C28: =COUNTIFS(Items!B:B,"15. Admin",Items!E:E,"Done") -> 0 | D28: =COUNTIFS(Items!B:B,"15. Admin",Items!E:E,"Verified") -> 0 | E28: =IFERROR((C28+D28)/B28,0) -> 0
A29: 2. Global UI | B29: =COUNTIF(Items!B:B,"2. Global UI") -> 4 | C29: =COUNTIFS(Items!B:B,"2. Global UI",Items!E:E,"Done") -> 0 | D29: =COUNTIFS(Items!B:B,"2. Global UI",Items!E:E,"Verified") -> 0 | E29: =IFERROR((C29+D29)/B29,0) -> 0
A30: 3. Legal Pages | B30: =COUNTIF(Items!B:B,"3. Legal Pages") -> 10 | C30: =COUNTIFS(Items!B:B,"3. Legal Pages",Items!E:E,"Done") -> 0 | D30: =COUNTIFS(Items!B:B,"3. Legal Pages",Items!E:E,"Verified") -> 0 | E30: =IFERROR((C30+D30)/B30,0) -> 0
A31: 4. Client Signup | B31: =COUNTIF(Items!B:B,"4. Client Signup") -> 3 | C31: =COUNTIFS(Items!B:B,"4. Client Signup",Items!E:E,"Done") -> 0 | D31: =COUNTIFS(Items!B:B,"4. Client Signup",Items!E:E,"Verified") -> 0 | E31: =IFERROR((C31+D31)/B31,0) -> 0
A32: 5. Pro Signup | B32: =COUNTIF(Items!B:B,"5. Pro Signup") -> 12 | C32: =COUNTIFS(Items!B:B,"5. Pro Signup",Items!E:E,"Done") -> 0 | D32: =COUNTIFS(Items!B:B,"5. Pro Signup",Items!E:E,"Verified") -> 0 | E32: =IFERROR((C32+D32)/B32,0) -> 0
A33: 6. Booking Flow | B33: =COUNTIF(Items!B:B,"6. Booking Flow") -> 4 | C33: =COUNTIFS(Items!B:B,"6. Booking Flow",Items!E:E,"Done") -> 0 | D33: =COUNTIFS(Items!B:B,"6. Booking Flow",Items!E:E,"Verified") -> 0 | E33: =IFERROR((C33+D33)/B33,0) -> 0
A34: 7. Payment | B34: =COUNTIF(Items!B:B,"7. Payment") -> 5 | C34: =COUNTIFS(Items!B:B,"7. Payment",Items!E:E,"Done") -> 0 | D34: =COUNTIFS(Items!B:B,"7. Payment",Items!E:E,"Verified") -> 0 | E34: =IFERROR((C34+D34)/B34,0) -> 0
A35: 8. Cancellation | B35: =COUNTIF(Items!B:B,"8. Cancellation") -> 6 | C35: =COUNTIFS(Items!B:B,"8. Cancellation",Items!E:E,"Done") -> 0 | D35: =COUNTIFS(Items!B:B,"8. Cancellation",Items!E:E,"Verified") -> 0 | E35: =IFERROR((C35+D35)/B35,0) -> 0
A36: 9. Account Settings | B36: =COUNTIF(Items!B:B,"9. Account Settings") -> 7 | C36: =COUNTIFS(Items!B:B,"9. Account Settings",Items!E:E,"Done") -> 0 | D36: =COUNTIFS(Items!B:B,"9. Account Settings",Items!E:E,"Verified") -> 0 | E36: =IFERROR((C36+D36)/B36,0) -> 0
A39: ★ CRITICAL ITEMS (must be Verified before public launch)
A40: CHG-046 | B40: STANDALONE FCRA Disclosure — Gilberg-compliant (single page, no other consent on it)
A41: CHG-045 | B41: Standalone Pro IC Agreement clickwrap (NOT bundled with ToS)
A42: CHG-131 | B42: SMS sending wrapper enforcing TCPA + FTSA quiet hours
A43: CHG-001 | B43: consent_records table immutability (no UPDATE/DELETE permissions)
A44: CHG-006 | B44: sms_consent_records 5-year retention
A45: CHG-013 | B45: GPC signal honored as CCPA opt-out
...

Sheet Items
A1: CHG ID | B1: Section | C1: Title | D1: Priority | E1: Status | F1: Owner | G1: Dependencies | H1: Acceptance Notes | I1: Date Started | J1: Date Completed | K1: Date Verified | L1: Lovable Session | M1: Blocker / Notes
A2: CHG-001 | B2: 1. Foundation | C2: Database schema: consent_records table | D2: P0 | E2: Not Started | F2: Lovable | G2: — | H2: Audit-immutable consent record table for every clickwrap acceptance
A3: CHG-002 | B3: 1. Foundation | C3: Database schema: legal_documents table | D3: P0 | E3: Not Started | F3: Lovable | G3: — | H3: Versioned legal document storage with current-version constraint
A4: CHG-003 | B4: 1. Foundation | C4: Database schema: user profile additions | D4: P0 | E4: Not Started | F4: Lovable | G4: CHG-001 | H4: Add age, state, account_status, marketing opt-ins, CCPA opt-out, arbitration opt-out fields
A5: CHG-004 | B5: 1. Foundation | C5: Database schema: pro_credentials table | D5: P0 | E5: Not Started | F5: Lovable | G5: CHG-003 | H5: Encrypted credential storage for business license / EIN / COI
A6: CHG-005 | B6: 1. Foundation | C6: Database schema: background_checks table | D6: P0 | E6: Not Started | F6: Lovable | G6: CHG-003 | H6: Status tracking for Checkr workflow; no raw report content
A7: CHG-006 | B7: 1. Foundation | C7: Database schema: sms_consent_records table | D7: P0 | E7: Not Started | F7: Lovable | G7: CHG-003 | H7: TCPA-compliant SMS consent records; 5-year retention
A8: CHG-007 | B8: 1. Foundation | C8: Database schema: audit_log table | D8: P0 | E8: Not Started | F8: Lovable | G8: — | H8: Append-only audit log for PII access, admin actions, consent changes
A9: CHG-008 | B9: 1. Foundation | C9: Environment variables setup | D9: P0 | E9: Not Started | F9: Nathan | G9: — | H9: Stripe, Checkr, Twilio, OneSignal, email, compliance contacts, OFAC keys
A10: CHG-009 | B10: 1. Foundation | C10: Install required dependencies | D10: P0 | E10: Not Started | F10: Lovable | G10: — | H10: Stripe, Supabase, Twilio, Resend, Checkr, Zod, react-hook-form, date-fns-tz
A11: CHG-010 | B11: 1. Foundation | C11: Constants file: legal & policy values | D11: P0 | E11: Not Started | F11: Lovable | G11: — | H11: Hard limits and policy constants in lib/legal-constants.ts
A12: CHG-011 | B12: 2. Global UI | C12: Site footer with legal links | D12: P0 | E12: Not Started | F12: Lovable | G12: CHG-010 | H12: Footer on every page with Do Not Sell, Limit SPI, legal page links
A13: CHG-012 | B13: 2. Global UI | C13: Cookie consent banner | D13: P0 | E13: Not Started | F13: Lovable | G13: CHG-001, CHG-013 | H13: First-visit banner with Accept all / Reject / Customize; persistent re-open via footer
... A91: CHG-201 | B91: 15. Admin | C91: DMCA Designated Agent registration | D91: P1 | E91: Not Started | F91: Nathan | G91: — | H91: Register at dmca.copyright.gov ($6); update Doc 01 Section 14.3

Sheet Session Plan
A1: Lovable Session Implementation Plan
A2: Each Lovable session implements a focused chunk of CHG items
A4: Session # | B4: Theme | C4: CHG Items | D4: Target Week | E4: Status
A5: Session 1 | B5: Foundation + Global UI | C5: CHG-001 to CHG-014 | D5: Week 1 | E5: Not Started
A6: Session 2 | B6: Legal Pages | C6: CHG-021 to CHG-030 | D6: Week 1-2 | E6: Not Started
A7: Session 3 | B7: Client Signup | C7: CHG-031 to CHG-033 | D7: Week 2 | E7: Not Started
A8: Session 4 | B8: Pro Signup (CRITICAL — Standalone FCRA) | C8: CHG-041 to CHG-052 | D8: Week 2-3 | E8: Not Started
A9: Session 5 | B9: Payment & Booking | C9: CHG-061 to CHG-064, CHG-081 to CHG-085, CHG-096 to CHG-101 | D9: Week 3-4 | E9: Not Started
A10: Session 6 | B10: Trust, Safety, SMS | C10: CHG-131 to CHG-152 | D10: Week 4-5 | E10: Not Started
A11: Session 7 | B11: Account Settings & Privacy | C11: CHG-111 to CHG-117 | D11: Week 5 | E11: Not Started
A12: Session 8 | B12: Accessibility, Mobile, Admin | C12: CHG-161, CHG-171 to CHG-201 | D12: Week 5-6 | E12: Not Started

Sheet Reference
A1: Reference: Status, Priority, Owner Definitions
A3: STATUS
A4: Not Started | B4: No work begun. Default state.
A5: In Progress | B5: Implementation underway. Date Started populated.
A6: Blocked | B6: Cannot proceed until a dependency or external decision resolves. Document in Blocker column.
A7: Done | B7: Implementation complete per Acceptance Notes. Date Completed populated. Awaiting verification.
A8: Verified | B8: Manually verified by Nathan against full Acceptance Criteria in Doc 15. Date Verified populated. SHIPPABLE.
A10: PRIORITY
A11: P0 | B11: Blocker. Cannot launch publicly without this. Most are legal/compliance critical.
A12: P1 | B12: Required before public launch. Cannot defer beyond Phase 6 of Doc 12 launch checklist.
A13: P2 | B13: Should ship within 30 days of public launch. Defer-able for soft launch only.
A14: P3 | B14: Nice-to-have. Roadmap. No launch dependency.
A17: OWNER
A18: Lovable | B18: Pure software implementation Lovable AI can do (UI, schema, business logic).
A19: Nathan | B19: Manual / operational work requiring real-world action (file LLC, buy insurance, register accounts).
A20: Nathan+Lovable | B20: Lovable can scaffold but Nathan must complete (e.g., vendor account setup + integration).
A21: Attorney | B21: Outside legal counsel.
A22: Vendor | B22: Third-party vendor (Stripe, Checkr, Twilio, OneSignal, etc.).
A23: — | B23: No specific owner; environmental setup.
